Workbook

Sheet Read Me
A1: Flourish Money: Unit Economics Model
A2: Built 2026-09-03. Purpose: answer 'what price and conversion does Flourish need to cover its costs' before touching more code.
A4: How to use
A5: 1. Inputs: every number in blue is editable. Yellow cells are the ones that swing the answer most. Column B is the app as built today (Canada + US, bank links open to free users, no prompt caching). Column C is the narrowed plan (Canada only, bank links behind Plus, caching on, Flora scoped to explain and calculate).
A6: 2. Unit Economics: cost and margin per paying user and per free user, then how many paying users it takes to break even and to reach $2k and $5k a month.
A7: 3. Scale P&L: monthly profit at 100 to 10,000 active users for both scenarios.
A8: 4. Pricing Sensitivity: Scenario B only. Breakeven paying users and trial signups needed at five price points and five conversion rates.
A10: What is fact vs assumption
A11: Facts from the codebase: prices in the Paywall, FREE_LIMIT of 5 coach messages, BETA_CAP of 30, no billing integration, no prompt caching.
A12: Facts from vendor pages (Sep 2026): Stripe Canada 2.9% + $0.30; Claude Sonnet $3/$15 per M tokens, cache reads 10%; Plaid bills Transactions monthly per Item and does not publish rates; Plaid trial allows 10 Production Items; Flinks starts at $500/mo for 200 connections on a 1-year contract, so it is not an option at beta scale.
A13: Everything else (conversion, churn, linked accounts, messages per user, token counts) is an assumption and is labelled as such in the Note column. Replace with real data as soon as you have 30 beta users.
A15: The one number to watch
... A18: Updated Sept 10, 2026: Scenario B now uses the decided prices (11.99 / 99.99 CAD, founding 79.99), 2 free coach messages a week, Stripe Billing 0.7% and Stripe Tax 0.5%, Netlify Pro USD 20. New sheet Plan Check computes the Dec 12 paying target from the two funnels and the hire triggers from the Finance rule.

Sheet Inputs
A1: Flourish Money — Unit Economics Inputs (all money in CAD unless noted)
A2: Blue = editable input. Yellow = key assumption to revisit. Black = formula. Green = pulled from another sheet.
A3: Assumption | B3: A: Current (CA+US) | C3: B: Narrowed (Canada, links Plus-only) | D3: Note / source
A4: Pricing
A5: Monthly price CAD | B5: 9.99 | C5: 11.99 | D5: DECISIONS.md (Sept 2026): $11.99/mo CAD. Column B keeps the old 9.99 for comparison.
A6: Annual price CAD | B6: 79.99 | C6: 99.99 | D6: DECISIONS.md: $99.99/yr CAD. Founding annual 79.99 is modelled in the Plan Check sheet.
A7: Monthly price USD | B7: 7.99 | C7: 0 | D7: App.jsx Paywall. Zero in B because US is dropped.
A8: Annual price USD | B8: 59.99 | C8: 0 | D8: App.jsx Paywall
A9: Share of paid users on annual plan | B9: 0.4 | C9: 0.4 | D9: Assumption. Annual is the default-selected plan in the paywall.
A10: Share of users in Canada | B10: 0.6 | C10: 1 | D10: Assumption for A. B is Canada-only by design.
A11: USD to CAD rate | B11: 1.36 | C11: 1.36 | D11: Assumption; update to current rate.
A12: Payment processing (Stripe Canada)
A13: Stripe domestic card % | B13: 0.029 | C13: 0.029 | D13: 2.9% + C$0.30 domestic. Source: profitvana.com/guides/stripe-fees-in-canada
A14: Stripe fixed fee per charge (CAD) | B14: 0.3 | C14: 0.3 | D14: Same source
A15: Stripe Billing (subscriptions) surcharge % | B15: 0.007 | C15: 0.007 | D15: Stripe Billing pay-as-you-go 0.7% of Billing volume (stripe.com/en-ca/pricing, Sept 2026).
A16: Extra % on non-Canadian cards (intl + FX) | B16: 0.025 | C16: 0.025 | D16: 1.5% international + 1% currency conversion. Applied to the US share of users.
A17: Bank connections (Plaid)
A18: Plaid Transactions, per connected account per month (USD) | B18: 0.3 | C18: 0.3 | D18: Plaid does not publish prices; billed monthly per Item while access_token exists (plaid.com/docs/account/billing). $0.30 is a commonly cited PAYG figure; replace with your quoted rate.
A19: Other Plaid cost per linked user per month (USD) | B19: 0.1 | C19: 0.1 | D19: Balance calls are per request; Auth is one-time per Item. Rough allowance. Plaid trial: max 10 Production Items free.
A20: Avg connected accounts per linking user | B20: 2.5 | C20: 2.5 | D20: Assumption (chequing + savings + credit card).
A21: Share of FREE users who link a bank | B21: 0.5 | C21: 0 | D21: A: links are open to everyone today. B: links gated behind Plus, so free users cost nothing here.
A22: Share of PAID users who link a bank | B22: 0.9 | C22: 0.9 | D22: Assumption
A23: AI coach (Flora on Claude API)
A24: Input price, $ per million tokens (USD) | B24: 3 | C24: 3 | D24: Sonnet standard rate $3 in / $15 out. Haiku 4.5 is $1 / $5. Source: benchlm.ai/anthropic/api-pricing (Sep 2026)
A25: Output price, $ per million tokens (USD) | B25: 15 | C25: 15 | D25: Same source
A26: Cached input price, $ per million tokens (USD) | B26: 0.3 | C26: 0.3 | D26: Cache reads are 10% of input rate. Requires the system prompt to be cache-marked in coach.js (it is not today).
A27: System prompt tokens per message (cacheable) | B27: 6000 | C27: 6000 | D27: Estimate from the coach prompt in App.jsx (profile, rules, tax tables, engine output).
A28: Fresh input tokens per message (history + data) | B28: 2000 | C28: 2000 | D28: Estimate
A29: Output tokens per message | B29: 350 | C29: 350 | D29: Estimate; prompt says be brief.
A30: Prompt caching enabled? (1 = yes, 0 = no) | B30: 0 | C30: 1 | D30: A: not implemented today. B: assumes you add cache_control to the system prompt.
A31: Coach messages per FREE user per month | B31: 5 | C31: 8.67 | D31: Free tier is 2 coach messages a week (usageLimits.js), about 8.67 a month.
A32: Coach messages per PAID user per month | B32: 40 | C32: 25 | D32: Assumption. B lower because Flora explains and calculates rather than open-ended advising.
A33: Fixed costs per month (CAD)
A34: Supabase Pro | B34: 34 | C34: 34 | D34: USD 25/mo converted. Free tier pauses inactive projects; Pro needed for auth reliability.
A35: Netlify Pro | B35: 27 | C35: 27 | D35: Netlify Pro is USD 20/mo on credit tiers since July 14, 2026 (function compute counts as credits).
A36: Google Workspace (hello@flourishmoney.app) | B36: 10 | C36: 10 | D36: DEPLOY.md DNS shows Google Workspace on the domain.
A37: Domain, Sentry, AI subscriptions (Claude plan with Claude Code, ChatGPT, Grok), QuickBooks, misc | B37: 329 | C37: 329 | D37: Sept 10 review: Sentry 35 + AI subscriptions about 250 + QuickBooks 30 + domain and misc. Scenario B fixed base now about 400 CAD; one cell feeds every breakeven figure.
A38: Funnel
A39: Trial-to-paid conversion | B39: 0.05 | C39: 0.08 | D39: Assumption. Consumer finance freemium typically 2 to 6%; B higher because free users are not getting the full product.
A40: Monthly paid churn | B40: 0.06 | C40: 0.05 | D40: Assumption. Subscription finance apps see 4 to 8% monthly.
...

Sheet Unit Economics
A1: Per-user economics, per month (CAD)
A3: Metric | B3: A: Current | C3: B: Narrowed | D3: How it is calculated
A4: Revenue per paying user
A5: Blended revenue per paid user / month | B5: =Inputs!$B$10*(Inputs!$B$9*Inputs!$B$6/12+(1-Inputs!$B$9)*Inputs!$B$5)+(1-Inputs!$B$10)*(Inputs!$B$9*Inputs!$B$8/12+(1-Inputs!$B$9)*Inputs!$B$7)*Inputs!$B$11 -> 8.8919547 | C5: =Inputs!$C$10*(Inputs!$C$9*Inputs!$C$6/12+(1-Inputs!$C$9)*Inputs!$C$5)+(1-Inputs!$C$10)*(Inputs!$C$9*Inputs!$C$8/12+(1-Inputs!$C$9)*Inputs!$C$7)*Inputs!$C$11 -> 10.527 | D5: CA share x CAD blended (annual/12 and monthly by plan mix) + US share x USD blended x FX
A6: Variable costs per paying user
A7: Payment processing | B7: =B5*(Inputs!$B$13+Inputs!$B$15+(1-Inputs!$B$10)*Inputs!$B$16)+Inputs!$B$14*(Inputs!$B$9/12+(1-Inputs!$B$9)) -> 0.59902991 | C7: =C5*(Inputs!$C$13+Inputs!$C$15+(1-Inputs!$C$10)*Inputs!$C$16)+Inputs!$C$14*(Inputs!$C$9/12+(1-Inputs!$C$9)) -> 0.568972 | D7: Revenue x (Stripe % + Billing % + intl % on US share) + fixed fee per charge (annual users are charged once per 12 months)
A8: Bank connections (Plaid) | B8: =Inputs!$B$22*(Inputs!$B$20*Inputs!$B$18+Inputs!$B$19)*Inputs!$B$11 -> 1.0404 | C8: =Inputs!$C$22*(Inputs!$C$20*Inputs!$C$18+Inputs!$C$19)*Inputs!$C$11 -> 1.0404 | D8: Share who link x (accounts x per-account + other) x FX
A9: AI coach (Claude) | B9: =Inputs!$B$32*((Inputs!$B$27*IF(Inputs!$B$30=1,Inputs!$B$26,Inputs!$B$24)+Inputs!$B$28*Inputs!$B$24+Inputs!$B$29*Inputs!$B$25)/1000000)*Inputs!$B$11 -> 1.5912 | C9: =Inputs!$C$32*((Inputs!$C$27*IF(Inputs!$C$30=1,Inputs!$C$26,Inputs!$C$24)+Inputs!$C$28*Inputs!$C$24+Inputs!$C$29*Inputs!$C$25)/1000000)*Inputs!$C$11 -> 0.4437 | D9: Messages x (system tokens at cached or full rate + fresh input + output) / 1M x FX
A10: Total variable cost per paid user | B10: =SUM(B7:B9) -> 3.2306299 | C10: =SUM(C7:C9) -> 2.053072
A11: Contribution margin per paid user / month | B11: =B5-B10 -> 5.6613248 | C11: =C5-C10 -> 8.473928 | D11: Revenue minus variable cost
A12: Contribution margin % | B12: =IF(B5=0,0,B11/B5) -> 0.63667944 | C12: =IF(C5=0,0,C11/C5) -> 0.80497084
A13: Lifetime contribution per paid user | B13: =IF(Inputs!$B$40=0,0,B11/Inputs!$B$40) -> 94.355413 | C13: =IF(Inputs!$C$40=0,0,C11/Inputs!$C$40) -> 169.47856 | D13: Margin / monthly churn. This is the ceiling on what you can spend to acquire one paying user.
A14: Cost of a FREE user (no revenue)
A15: Bank connections (Plaid) | B15: =Inputs!$B$21*(Inputs!$B$20*Inputs!$B$18+Inputs!$B$19)*Inputs!$B$11 -> 0.578 | C15: =Inputs!$C$21*(Inputs!$C$20*Inputs!$C$18+Inputs!$C$19)*Inputs!$C$11 -> 0 | D15: Same formula using the free-user link share
A16: AI coach (Claude) | B16: =Inputs!$B$31*((Inputs!$B$27*IF(Inputs!$B$30=1,Inputs!$B$26,Inputs!$B$24)+Inputs!$B$28*Inputs!$B$24+Inputs!$B$29*Inputs!$B$25)/1000000)*Inputs!$B$11 -> 0.1989 | C16: =Inputs!$C$31*((Inputs!$C$27*IF(Inputs!$C$30=1,Inputs!$C$26,Inputs!$C$24)+Inputs!$C$28*Inputs!$C$24+Inputs!$C$29*Inputs!$C$25)/1000000)*Inputs!$C$11 -> 0.15387516 | D16: Free users get FREE_LIMIT messages
A17: Total cost per free user / month | B17: =B15+B16 -> 0.7769 | C17: =C15+C16 -> 0.15387516
A18: Mix and breakeven
A19: Active free users per paying user | B19: =IF(Inputs!$B$39=0,0,(1-Inputs!$B$39)*Inputs!$B$41/Inputs!$B$39) -> 9.5 | C19: =IF(Inputs!$C$39=0,0,(1-Inputs!$C$39)*Inputs!$C$41/Inputs!$C$39) -> 3.45 | D19: (1 - conversion) x free retention / conversion
A20: Margin per paid user after carrying its free users | B20: =B11-B19*B17 -> -1.7192252 | C20: =C11-C19*C17 -> 7.9430587 | D20: Margin minus (free users per paid x free cost)
A21: Fixed costs / month | B21: =SUM(Inputs!$B$34:$B$37) -> 400 | C21: =SUM(Inputs!$C$34:$C$37) -> 400 | D21: Sum of fixed cost inputs
A22: Paying users to break even | B22: =IF(B20<=0,"never",ROUNDUP(B21/B20,0)) -> never | C22: =IF(C20<=0,"never",ROUNDUP(C21/C20,0)) -> 51 | D22: Fixed / net margin per paid user
A23: Total active users at breakeven | B23: =IF(ISNUMBER(B22),ROUNDUP(B22*(1+B19),0),"never") -> never | C23: =IF(ISNUMBER(C22),ROUNDUP(C22*(1+C19),0),"never") -> 227 | D23: Paid x (1 + free per paid)
A24: Cumulative trial signups needed | B24: =IF(ISNUMBER(B22),ROUNDUP(B22/Inputs!$B$39,0),"never") -> never | C24: =IF(ISNUMBER(C22),ROUNDUP(C22/Inputs!$C$39,0),"never") -> 638 | D24: Paid / conversion (ignores churn replacement)
A25: Paying users for $2,000/mo profit | B25: =IF(B20<=0,"never",ROUNDUP((B21+2000)/B20,0)) -> never | C25: =IF(C20<=0,"never",ROUNDUP((C21+2000)/C20,0)) -> 303
A26: Paying users for $5,000/mo profit | B26: =IF(B20<=0,"never",ROUNDUP((B21+5000)/B20,0)) -> never | C26: =IF(C20<=0,"never",ROUNDUP((C21+5000)/C20,0)) -> 680
A27: New paying users needed per month just to replace churn (at $5k level) | B27: =IF(ISNUMBER(B26),ROUNDUP(B26*Inputs!$B$40,0),"n/a") -> n/a | C27: =IF(ISNUMBER(C26),ROUNDUP(C26*Inputs!$C$40,0),"n/a") -> 34 | D27: Paid base x churn. Divide by conversion for signups needed per month.

Sheet Scale P&L
A1: Monthly P&L at different user counts (CAD)
A2: Total active users = paying + retained free. Paid share comes from the free-per-paid ratio on Unit Economics.
A4: Scenario A: Current (CA+US)
A5: Total active users | B5: Paying users | C5: Free users | D5: Revenue | E5: Variable cost (paid) | F5: Free-user cost | G5: Fixed cost | H5: Profit / month | I5: Margin %
A6: 100 | B6: =ROUND(A6/(1+'Unit Economics'!$B$19),0) -> 10 | C6: =A6-B6 -> 90 | D6: =B6*'Unit Economics'!$B$5 -> 88.919547 | E6: =-B6*'Unit Economics'!$B$10 -> -32.306299 | F6: =-C6*'Unit Economics'!$B$17 -> -69.921 | G6: =-'Unit Economics'!$B$21 -> -400 | H6: =SUM(D6:G6) -> -413.30775 | I6: =IF(D6=0,0,H6/D6) -> -4.6481091
A7: 250 | B7: =ROUND(A7/(1+'Unit Economics'!$B$19),0) -> 24 | C7: =A7-B7 -> 226 | D7: =B7*'Unit Economics'!$B$5 -> 213.40691 | E7: =-B7*'Unit Economics'!$B$10 -> -77.535118 | F7: =-C7*'Unit Economics'!$B$17 -> -175.5794 | G7: =-'Unit Economics'!$B$21 -> -400 | H7: =SUM(D7:G7) -> -439.70761 | I7: =IF(D7=0,0,H7/D7) -> -2.0604188
A8: 500 | B8: =ROUND(A8/(1+'Unit Economics'!$B$19),0) -> 48 | C8: =A8-B8 -> 452 | D8: =B8*'Unit Economics'!$B$5 -> 426.81382 | E8: =-B8*'Unit Economics'!$B$10 -> -155.07024 | F8: =-C8*'Unit Economics'!$B$17 -> -351.1588 | G8: =-'Unit Economics'!$B$21 -> -400 | H8: =SUM(D8:G8) -> -479.41521 | I8: =IF(D8=0,0,H8/D8) -> -1.123242
A9: 1000 | B9: =ROUND(A9/(1+'Unit Economics'!$B$19),0) -> 95 | C9: =A9-B9 -> 905 | D9: =B9*'Unit Economics'!$B$5 -> 844.73569 | E9: =-B9*'Unit Economics'!$B$10 -> -306.90984 | F9: =-C9*'Unit Economics'!$B$17 -> -703.0945 | G9: =-'Unit Economics'!$B$21 -> -400 | H9: =SUM(D9:G9) -> -565.26865 | I9: =IF(D9=0,0,H9/D9) -> -0.66916629
A10: 2500 | B10: =ROUND(A10/(1+'Unit Economics'!$B$19),0) -> 238 | C10: =A10-B10 -> 2262 | D10: =B10*'Unit Economics'!$B$5 -> 2116.2852 | E10: =-B10*'Unit Economics'!$B$10 -> -768.88992 | F10: =-C10*'Unit Economics'!$B$17 -> -1757.3478 | G10: =-'Unit Economics'!$B$21 -> -400 | H10: =SUM(D10:G10) -> -809.95251 | I10: =IF(D10=0,0,H10/D10) -> -0.3827237
A11: 5000 | B11: =ROUND(A11/(1+'Unit Economics'!$B$19),0) -> 476 | C11: =A11-B11 -> 4524 | D11: =B11*'Unit Economics'!$B$5 -> 4232.5704 | E11: =-B11*'Unit Economics'!$B$10 -> -1537.7798 | F11: =-C11*'Unit Economics'!$B$17 -> -3514.6956 | G11: =-'Unit Economics'!$B$21 -> -400 | H11: =SUM(D11:G11) -> -1219.905 | I11: =IF(D11=0,0,H11/D11) -> -0.28821848
A12: 10000 | B12: =ROUND(A12/(1+'Unit Economics'!$B$19),0) -> 952 | C12: =A12-B12 -> 9048 | D12: =B12*'Unit Economics'!$B$5 -> 8465.1408 | E12: =-B12*'Unit Economics'!$B$10 -> -3075.5597 | F12: =-C12*'Unit Economics'!$B$17 -> -7029.3912 | G12: =-'Unit Economics'!$B$21 -> -400 | H12: =SUM(D12:G12) -> -2039.81 | I12: =IF(D12=0,0,H12/D12) -> -0.24096587
A15: Scenario B: Narrowed (Canada, links Plus-only)
A16: Total active users | B16: Paying users | C16: Free users | D16: Revenue | E16: Variable cost (paid) | F16: Free-user cost | G16: Fixed cost | H16: Profit / month | I16: Margin %
A17: 100 | B17: =ROUND(A17/(1+'Unit Economics'!$C$19),0) -> 22 | C17: =A17-B17 -> 78 | D17: =B17*'Unit Economics'!$C$5 -> 231.594 | E17: =-B17*'Unit Economics'!$C$10 -> -45.167584 | F17: =-C17*'Unit Economics'!$C$17 -> -12.002262 | G17: =-'Unit Economics'!$C$21 -> -400 | H17: =SUM(D17:G17) -> -225.57585 | I17: =IF(D17=0,0,H17/D17) -> -0.97401421
A18: 250 | B18: =ROUND(A18/(1+'Unit Economics'!$C$19),0) -> 56 | C18: =A18-B18 -> 194 | D18: =B18*'Unit Economics'!$C$5 -> 589.512 | E18: =-B18*'Unit Economics'!$C$10 -> -114.97203 | F18: =-C18*'Unit Economics'!$C$17 -> -29.851781 | G18: =-'Unit Economics'!$C$21 -> -400 | H18: =SUM(D18:G18) -> 44.688187 | I18: =IF(D18=0,0,H18/D18) -> 0.07580539
A19: 500 | B19: =ROUND(A19/(1+'Unit Economics'!$C$19),0) -> 112 | C19: =A19-B19 -> 388 | D19: =B19*'Unit Economics'!$C$5 -> 1179.024 | E19: =-B19*'Unit Economics'!$C$10 -> -229.94406 | F19: =-C19*'Unit Economics'!$C$17 -> -59.703562 | G19: =-'Unit Economics'!$C$21 -> -400 | H19: =SUM(D19:G19) -> 489.37637 | I19: =IF(D19=0,0,H19/D19) -> 0.41506905
A20: 1000 | B20: =ROUND(A20/(1+'Unit Economics'!$C$19),0) -> 225 | C20: =A20-B20 -> 775 | D20: =B20*'Unit Economics'!$C$5 -> 2368.575 | E20: =-B20*'Unit Economics'!$C$10 -> -461.9412 | F20: =-C20*'Unit Economics'!$C$17 -> -119.25325 | G20: =-'Unit Economics'!$C$21 -> -400 | H20: =SUM(D20:G20) -> 1387.3806 | I20: =IF(D20=0,0,H20/D20) -> 0.58574483
A21: 2500 | B21: =ROUND(A21/(1+'Unit Economics'!$C$19),0) -> 562 | C21: =A21-B21 -> 1938 | D21: =B21*'Unit Economics'!$C$5 -> 5916.174 | E21: =-B21*'Unit Economics'!$C$10 -> -1153.8265 | F21: =-C21*'Unit Economics'!$C$17 -> -298.21006 | G21: =-'Unit Economics'!$C$21 -> -400 | H21: =SUM(D21:G21) -> 4064.1375 | I21: =IF(D21=0,0,H21/D21) -> 0.68695368
A22: 5000 | B22: =ROUND(A22/(1+'Unit Economics'!$C$19),0) -> 1124 | C22: =A22-B22 -> 3876 | D22: =B22*'Unit Economics'!$C$5 -> 11832.348 | E22: =-B22*'Unit Economics'!$C$10 -> -2307.6529 | F22: =-C22*'Unit Economics'!$C$17 -> -596.42012 | G22: =-'Unit Economics'!$C$21 -> -400 | H22: =SUM(D22:G22) -> 8528.275 | I22: =IF(D22=0,0,H22/D22) -> 0.72075931
A23: 10000 | B23: =ROUND(A23/(1+'Unit Economics'!$C$19),0) -> 2247 | C23: =A23-B23 -> 7753 | D23: =B23*'Unit Economics'!$C$5 -> 23654.169 | E23: =-B23*'Unit Economics'!$C$10 -> -4613.2528 | F23: =-C23*'Unit Economics'!$C$17 -> -1192.9941 | G23: =-'Unit Economics'!$C$21 -> -400 | H23: =SUM(D23:G23) -> 17447.922 | I23: =IF(D23=0,0,H23/D23) -> 0.73762566

Sheet Pricing Sensitivity
A1: Scenario B, monthly-plan price vs conversion (CAD, Canada only)
A2: Each cell = paying users needed to break even at that price and conversion. Uses Scenario B costs; annual plan share set to 0 here so the price is a pure monthly price.
A4: Variable cost per paid user excl. payment fees (Scenario B) | B4: ='Unit Economics'!$C$8+'Unit Economics'!$C$9 -> 1.4841
A5: Cost per free user (Scenario B) | B5: ='Unit Economics'!$C$17 -> 0.15387516
A6: Fixed costs (Scenario B) | B6: ='Unit Economics'!$C$21 -> 400
A7: Free retention (Scenario B) | B7: =Inputs!$C$41 -> 0.3
A9: Monthly price (CAD) | B9: Payment fees | C9: Margin per paid user | D9: Margin %
A10: 7.99 | B10: =A10*(Inputs!$C$13+Inputs!$C$15)+Inputs!$C$14 -> 0.58764 | C10: =A10-B10-$B$4 -> 5.91826 | D10: =IF(A10=0,0,C10/A10) -> 0.74070839
A11: 9.99 | B11: =A11*(Inputs!$C$13+Inputs!$C$15)+Inputs!$C$14 -> 0.65964 | C11: =A11-B11-$B$4 -> 7.84626 | D11: =IF(A11=0,0,C11/A11) -> 0.78541141
A12: 12.99 | B12: =A12*(Inputs!$C$13+Inputs!$C$15)+Inputs!$C$14 -> 0.76764 | C12: =A12-B12-$B$4 -> 10.73826 | D12: =IF(A12=0,0,C12/A12) -> 0.82665589
A13: 14.99 | B13: =A13*(Inputs!$C$13+Inputs!$C$15)+Inputs!$C$14 -> 0.83964 | C13: =A13-B13-$B$4 -> 12.66626 | D13: =IF(A13=0,0,C13/A13) -> 0.84498065
A14: 19.99 | B14: =A14*(Inputs!$C$13+Inputs!$C$15)+Inputs!$C$14 -> 1.01964 | C14: =A14-B14-$B$4 -> 17.48626 | D14: =IF(A14=0,0,C14/A14) -> 0.87475038
A17: Paying users to break even
A18: Price \ Conversion | B18: 0.02 | C18: 0.04 | D18: 0.06 | E18: 0.08 | F18: 0.12
A19: =A10 -> 7.99 | B19: =IF(($C10-((1-B$18)*$B$7/B$18)*$B$5)<=0,"never",ROUNDUP($B$6/($C10-((1-B$18)*$B$7/B$18)*$B$5),0)) -> 110 | C19: =IF(($C10-((1-C$18)*$B$7/C$18)*$B$5)<=0,"never",ROUNDUP($B$6/($C10-((1-C$18)*$B$7/C$18)*$B$5),0)) -> 84 | D19: =IF(($C10-((1-D$18)*$B$7/D$18)*$B$5)<=0,"never",ROUNDUP($B$6/($C10-((1-D$18)*$B$7/D$18)*$B$5),0)) -> 77 | E19: =IF(($C10-((1-E$18)*$B$7/E$18)*$B$5)<=0,"never",ROUNDUP($B$6/($C10-((1-E$18)*$B$7/E$18)*$B$5),0)) -> 75 | F19: =IF(($C10-((1-F$18)*$B$7/F$18)*$B$5)<=0,"never",ROUNDUP($B$6/($C10-((1-F$18)*$B$7/F$18)*$B$5),0)) -> 72
A20: =A11 -> 9.99 | B20: =IF(($C11-((1-B$18)*$B$7/B$18)*$B$5)<=0,"never",ROUNDUP($B$6/($C11-((1-B$18)*$B$7/B$18)*$B$5),0)) -> 72 | C20: =IF(($C11-((1-C$18)*$B$7/C$18)*$B$5)<=0,"never",ROUNDUP($B$6/($C11-((1-C$18)*$B$7/C$18)*$B$5),0)) -> 60 | D20: =IF(($C11-((1-D$18)*$B$7/D$18)*$B$5)<=0,"never",ROUNDUP($B$6/($C11-((1-D$18)*$B$7/D$18)*$B$5),0)) -> 57 | E20: =IF(($C11-((1-E$18)*$B$7/E$18)*$B$5)<=0,"never",ROUNDUP($B$6/($C11-((1-E$18)*$B$7/E$18)*$B$5),0)) -> 55 | F20: =IF(($C11-((1-F$18)*$B$7/F$18)*$B$5)<=0,"never",ROUNDUP($B$6/($C11-((1-F$18)*$B$7/F$18)*$B$5),0)) -> 54
A21: =A12 -> 12.99 | B21: =IF(($C12-((1-B$18)*$B$7/B$18)*$B$5)<=0,"never",ROUNDUP($B$6/($C12-((1-B$18)*$B$7/B$18)*$B$5),0)) -> 48 | C21: =IF(($C12-((1-C$18)*$B$7/C$18)*$B$5)<=0,"never",ROUNDUP($B$6/($C12-((1-C$18)*$B$7/C$18)*$B$5),0)) -> 42 | D21: =IF(($C12-((1-D$18)*$B$7/D$18)*$B$5)<=0,"never",ROUNDUP($B$6/($C12-((1-D$18)*$B$7/D$18)*$B$5),0)) -> 40 | E21: =IF(($C12-((1-E$18)*$B$7/E$18)*$B$5)<=0,"never",ROUNDUP($B$6/($C12-((1-E$18)*$B$7/E$18)*$B$5),0)) -> 40 | F21: =IF(($C12-((1-F$18)*$B$7/F$18)*$B$5)<=0,"never",ROUNDUP($B$6/($C12-((1-F$18)*$B$7/F$18)*$B$5),0)) -> 39
A22: =A13 -> 14.99 | B22: =IF(($C13-((1-B$18)*$B$7/B$18)*$B$5)<=0,"never",ROUNDUP($B$6/($C13-((1-B$18)*$B$7/B$18)*$B$5),0)) -> 39 | C22: =IF(($C13-((1-C$18)*$B$7/C$18)*$B$5)<=0,"never",ROUNDUP($B$6/($C13-((1-C$18)*$B$7/C$18)*$B$5),0)) -> 35 | D22: =IF(($C13-((1-D$18)*$B$7/D$18)*$B$5)<=0,"never",ROUNDUP($B$6/($C13-((1-D$18)*$B$7/D$18)*$B$5),0)) -> 34 | E22: =IF(($C13-((1-E$18)*$B$7/E$18)*$B$5)<=0,"never",ROUNDUP($B$6/($C13-((1-E$18)*$B$7/E$18)*$B$5),0)) -> 33 | F22: =IF(($C13-((1-F$18)*$B$7/F$18)*$B$5)<=0,"never",ROUNDUP($B$6/($C13-((1-F$18)*$B$7/F$18)*$B$5),0)) -> 33
A23: =A14 -> 19.99 | B23: =IF(($C14-((1-B$18)*$B$7/B$18)*$B$5)<=0,"never",ROUNDUP($B$6/($C14-((1-B$18)*$B$7/B$18)*$B$5),0)) -> 27 | C23: =IF(($C14-((1-C$18)*$B$7/C$18)*$B$5)<=0,"never",ROUNDUP($B$6/($C14-((1-C$18)*$B$7/C$18)*$B$5),0)) -> 25 | D23: =IF(($C14-((1-D$18)*$B$7/D$18)*$B$5)<=0,"never",ROUNDUP($B$6/($C14-((1-D$18)*$B$7/D$18)*$B$5),0)) -> 24 | E23: =IF(($C14-((1-E$18)*$B$7/E$18)*$B$5)<=0,"never",ROUNDUP($B$6/($C14-((1-E$18)*$B$7/E$18)*$B$5),0)) -> 24 | F23: =IF(($C14-((1-F$18)*$B$7/F$18)*$B$5)<=0,"never",ROUNDUP($B$6/($C14-((1-F$18)*$B$7/F$18)*$B$5),0)) -> 24
A26: Cumulative trial signups needed for $3,000/mo profit
A27: Price \ Conversion | B27: =B18 -> 0.02 | C27: =C18 -> 0.04 | D27: =D18 -> 0.06 | E27: =E18 -> 0.08 | F27: =F18 -> 0.12
A28: =A10 -> 7.99 | B28: =IF(($C10-((1-B$27)*$B$7/B$27)*$B$5)<=0,"never",ROUNDUP(($B$6+3000)/($C10-((1-B$27)*$B$7/B$27)*$B$5)/B$27,0)) -> 46496 | C28: =IF(($C10-((1-C$27)*$B$7/C$27)*$B$5)<=0,"never",ROUNDUP(($B$6+3000)/($C10-((1-C$27)*$B$7/C$27)*$B$5)/C$27,0)) -> 17671 | D28: =IF(($C10-((1-D$27)*$B$7/D$27)*$B$5)<=0,"never",ROUNDUP(($B$6+3000)/($C10-((1-D$27)*$B$7/D$27)*$B$5)/D$27,0)) -> 10908 | E28: =IF(($C10-((1-E$27)*$B$7/E$27)*$B$5)<=0,"never",ROUNDUP(($B$6+3000)/($C10-((1-E$27)*$B$7/E$27)*$B$5)/E$27,0)) -> 7889 | F28: =IF(($C10-((1-F$27)*$B$7/F$27)*$B$5)<=0,"never",ROUNDUP(($B$6+3000)/($C10-((1-F$27)*$B$7/F$27)*$B$5)/F$27,0)) -> 5078
A29: =A11 -> 9.99 | B29: =IF(($C11-((1-B$27)*$B$7/B$27)*$B$5)<=0,"never",ROUNDUP(($B$6+3000)/($C11-((1-B$27)*$B$7/B$27)*$B$5)/B$27,0)) -> 30443 | C29: =IF(($C11-((1-C$27)*$B$7/C$27)*$B$5)<=0,"never",ROUNDUP(($B$6+3000)/($C11-((1-C$27)*$B$7/C$27)*$B$5)/C$27,0)) -> 12615 | D29: =IF(($C11-((1-D$27)*$B$7/D$27)*$B$5)<=0,"never",ROUNDUP(($B$6+3000)/($C11-((1-D$27)*$B$7/D$27)*$B$5)/D$27,0)) -> 7956 | E29: =IF(($C11-((1-E$27)*$B$7/E$27)*$B$5)<=0,"never",ROUNDUP(($B$6+3000)/($C11-((1-E$27)*$B$7/E$27)*$B$5)/E$27,0)) -> 5810 | F29: =IF(($C11-((1-F$27)*$B$7/F$27)*$B$5)<=0,"never",ROUNDUP(($B$6+3000)/($C11-((1-F$27)*$B$7/F$27)*$B$5)/F$27,0)) -> 3774
A30: =A12 -> 12.99 | B30: =IF(($C12-((1-B$27)*$B$7/B$27)*$B$5)<=0,"never",ROUNDUP(($B$6+3000)/($C12-((1-B$27)*$B$7/B$27)*$B$5)/B$27,0)) -> 20056 | C30: =IF(($C12-((1-C$27)*$B$7/C$27)*$B$5)<=0,"never",ROUNDUP(($B$6+3000)/($C12-((1-C$27)*$B$7/C$27)*$B$5)/C$27,0)) -> 8827 | D30: =IF(($C12-((1-D$27)*$B$7/D$27)*$B$5)<=0,"never",ROUNDUP(($B$6+3000)/($C12-((1-D$27)*$B$7/D$27)*$B$5)/D$27,0)) -> 5659 | E30: =IF(($C12-((1-E$27)*$B$7/E$27)*$B$5)<=0,"never",ROUNDUP(($B$6+3000)/($C12-((1-E$27)*$B$7/E$27)*$B$5)/E$27,0)) -> 4164 | F30: =IF(($C12-((1-F$27)*$B$7/F$27)*$B$5)<=0,"never",ROUNDUP(($B$6+3000)/($C12-((1-F$27)*$B$7/F$27)*$B$5)/F$27,0)) -> 2725
A31: =A13 -> 14.99 | B31: =IF(($C13-((1-B$27)*$B$7/B$27)*$B$5)<=0,"never",ROUNDUP(($B$6+3000)/($C13-((1-B$27)*$B$7/B$27)*$B$5)/B$27,0)) -> 16340 | C31: =IF(($C13-((1-C$27)*$B$7/C$27)*$B$5)<=0,"never",ROUNDUP(($B$6+3000)/($C13-((1-C$27)*$B$7/C$27)*$B$5)/C$27,0)) -> 7354 | D31: =IF(($C13-((1-D$27)*$B$7/D$27)*$B$5)<=0,"never",ROUNDUP(($B$6+3000)/($C13-((1-D$27)*$B$7/D$27)*$B$5)/D$27,0)) -> 4745 | E31: =IF(($C13-((1-E$27)*$B$7/E$27)*$B$5)<=0,"never",ROUNDUP(($B$6+3000)/($C13-((1-E$27)*$B$7/E$27)*$B$5)/E$27,0)) -> 3503 | F31: =IF(($C13-((1-F$27)*$B$7/F$27)*$B$5)<=0,"never",ROUNDUP(($B$6+3000)/($C13-((1-F$27)*$B$7/F$27)*$B$5)/F$27,0)) -> 2299
A32: =A14 -> 19.99 | B32: =IF(($C14-((1-B$27)*$B$7/B$27)*$B$5)<=0,"never",ROUNDUP(($B$6+3000)/($C14-((1-B$27)*$B$7/B$27)*$B$5)/B$27,0)) -> 11167 | C32: =IF(($C14-((1-C$27)*$B$7/C$27)*$B$5)<=0,"never",ROUNDUP(($B$6+3000)/($C14-((1-C$27)*$B$7/C$27)*$B$5)/C$27,0)) -> 5190 | D32: =IF(($C14-((1-D$27)*$B$7/D$27)*$B$5)<=0,"never",ROUNDUP(($B$6+3000)/($C14-((1-D$27)*$B$7/D$27)*$B$5)/D$27,0)) -> 3381 | E32: =IF(($C14-((1-E$27)*$B$7/E$27)*$B$5)<=0,"never",ROUNDUP(($B$6+3000)/($C14-((1-E$27)*$B$7/E$27)*$B$5)/E$27,0)) -> 2507 | F32: =IF(($C14-((1-F$27)*$B$7/F$27)*$B$5)<=0,"never",ROUNDUP(($B$6+3000)/($C14-((1-F$27)*$B$7/F$27)*$B$5)/F$27,0)) -> 1653

Sheet Plan Check
A1: Plan Check: Dec 12 target and hire triggers (all formulas read Inputs)
A3: Paying households by Dec 12
A4: From invited households (invitations x start rate x pay rate) | B4: =Inputs!B46*Inputs!B47*Inputs!B53 -> 48.75
A5: From self-serve trials (started x expired share x conversion) | B5: =Inputs!B54*Inputs!B55*Inputs!B49 -> 5.2
A6: Total paying by Dec 12 (commit 50; stretch 100 needs 250 invitations and 300 self-serve) | B6: =B4+B5 -> 53.95
A7: Cash collected before tax if invited take founding annual and self-serve pay two months | B7: =B4*Inputs!B44+B5*Inputs!C5*2 -> 4024.2085
A8: MRR-equivalent at Dec 12 | B8: =B4*Inputs!B44/12+B5*Inputs!C5 -> 387.30737
A9: Started trials in all (invited started plus self-serve) | B9: =Inputs!B46*Inputs!B47+Inputs!B54 -> 227.5
A10: Hire triggers
A11: Rule: 0.7 x MRR minus fixed costs (Inputs B52, about 400) minus existing payroll >= 2 x the new hire's loaded cost, three consecutive months, plus three months of cash. Loaded costs sourced Sept 10 (People review).
A13: Order | B13: Role | C13: Loaded cost / month | D13: Existing payroll before this hire | E13: MRR needed (formula) | F13: Trigger (rounded up to 500) | G13: Paying households at trigger
A14: 1 | B14: Support and Community Lead (part-time employee) | C14: 2300 | D14: =0 -> 0 | E14: =(Inputs!$B$52+D14+2*C14)/Inputs!$B$51 -> 7142.8571 | F14: =CEILING(MAX(E14,0),500) -> 7500 | G14: =ROUND(F14/Inputs!$B$50,0) -> 789
A15: 2 | B15: Bookkeeper (part-time contractor) | C15: 800 | D15: =D14+C14 -> 2300 | E15: =(Inputs!$B$52+D15+2*C15)/Inputs!$B$51 -> 6142.8571 | F15: =CEILING(MAX(E15,F14*1.05),500) -> 8000 | G15: =ROUND(F15/Inputs!$B$50,0) -> 842
A16: 3 | B16: Growth Marketer | C16: 6000 | D16: =D15+C15 -> 3100 | E16: =(Inputs!$B$52+D16+2*C16)/Inputs!$B$51 -> 22142.857 | F16: =CEILING(MAX(E16,F15*1.05),500) -> 22500 | G16: =ROUND(F16/Inputs!$B$50,0) -> 2368
A17: 4 | B17: Engineer 1 (senior base about 120k x 1.2) | C17: 12000 | D17: =D16+C16 -> 9100 | E17: =(Inputs!$B$52+D17+2*C17)/Inputs!$B$51 -> 47857.143 | F17: =CEILING(MAX(E17,F16*1.05),500) -> 48000 | G17: =ROUND(F17/Inputs!$B$50,0) -> 5053
A18: 5 | B18: Product Lead + Product Designer (about 90k base each x 1.2) | C18: 18000 | D18: =D17+C17 -> 21100 | E18: =(Inputs!$B$52+D18+2*C18)/Inputs!$B$51 -> 82142.857 | F18: =CEILING(MAX(E18,F17*1.05),500) -> 82500 | G18: =ROUND(F18/Inputs!$B$50,0) -> 8684
A19: 6 | B19: QA Engineer (about 85k x 1.2) | C19: 8500 | D19: =D18+C18 -> 39100 | E19: =(Inputs!$B$52+D19+2*C19)/Inputs!$B$51 -> 80714.286 | F19: =CEILING(MAX(E19,F18*1.05),500) -> 87000 | G19: =ROUND(F19/Inputs!$B$50,0) -> 9158
A20: 7 | B20: Data Analyst (about 85k x 1.2) | C20: 8500 | D20: =D19+C19 -> 47600 | E20: =(Inputs!$B$52+D20+2*C20)/Inputs!$B$51 -> 92857.143 | F20: =CEILING(MAX(E20,F19*1.05),500) -> 93000 | G20: =ROUND(F20/Inputs!$B$50,0) -> 9789
A21: 8 | B21: Partnerships Lead (about 85k x 1.2 plus commission) | C21: 8500 | D21: =D20+C20 -> 56100 | E21: =(Inputs!$B$52+D21+2*C21)/Inputs!$B$51 -> 105000 | F21: =CEILING(MAX(E21,F20*1.05),500) -> 105000 | G21: =ROUND(F21/Inputs!$B$50,0) -> 11053
A22: 9 | B22: Counsel (retained) | C22: 2500 | D22: =D21+C21 -> 64600 | E22: =(Inputs!$B$52+D22+2*C22)/Inputs!$B$51 -> 100000 | F22: =CEILING(MAX(E22,F21*1.05),500) -> 110500 | G22: =ROUND(F22/Inputs!$B$50,0) -> 11632
A23: 10 | B23: Ops Manager | C23: 6000 | D23: =D22+C22 -> 67100 | E23: =(Inputs!$B$52+D23+2*C23)/Inputs!$B$51 -> 113571.43 | F23: =CEILING(MAX(E23,F22*1.05),500) -> 116500 | G23: =ROUND(F23/Inputs!$B$50,0) -> 12263

Sheet Channels
A1: Channel forecast to December 12 (started trials) and weekly actuals from signup_completed source and utm_source
A3: Channel | B3: Funnel | C3: Forecast started trials by Dec 12 (commit) | D3: Stretch | E3: W1 actual | F3: W2 actual | G3: W3 actual | H3: W4 actual | I3: W5 actual | J3: W6 actual | K3: W7 actual | L3: W8 actual | M3: W9 actual | N3: W10 actual | O3: W11 actual | P3: W12 actual | Q3: W13 actual
A4: Personal invitations (founder network, prior correspondents) | B4: invited | C4: 78 | D4: 120
A5: Waitlist rows under six months old, launch email | B5: invited | C5: 10 | D5: 30
A6: Member referrals (who invited you) | B6: invited | C6: 10 | D6: 25
A7: Open web signup from Oct 19 (social, community, PR) | B7: self_serve | C7: 60 | D7: 120
A8: App Store from mid November | B8: self_serve | C8: 20 | D8: 60
A9: CCB clawback page and other wedge pages | B9: self_serve | C9: 20 | D9: 60
A10: Paid test Nov 2 to 15 | B10: self_serve | C10: 25 | D10: 35
A11: Partner code (letter of intent) | B11: self_serve | C11: 5 | D11: 25
A12: Invited started, total | C12: =SUMIF(B4:B11,"invited",C4:C11) -> 98 | D12: =SUMIF(B4:B11,"invited",D4:D11) -> 175
A13: Self-serve started, total | C13: =SUMIF(B4:B11,"self_serve",C4:C11) -> 130 | D13: =SUMIF(B4:B11,"self_serve",D4:D11) -> 300
A14: All started trials | C14: =C12+C13 -> 228 | D14: =D12+D13 -> 475
A16: Fill one weekly actual column every Monday (week 1 = Sept 14 to 20). Forecast cells are blue and editable; invited starts here equal Inputs invitations x start rate (150 x 0.65, about 98) and self-serve equals Inputs self-serve trials (130); keep them equal when either changes.

Sheet Cash
A1: Thirteen-week cash view, September 14 to December 12, 2026 (CAD, before tax)
A2: Outflows
A3: Fixed costs, 3 months (Inputs B52) | B3: =Inputs!B52*3 -> 1200
A4: Lawyer, fixed-fee review (estimate) | B4: 2500
A5: Trademark filing, CIPO fees plus agent (estimate) | B5: 1000
A6: Paid test | B6: 300
A7: QuickBooks, 3 months | B7: 90
A8: Total outflows | B8: =SUM(B3:B7) -> 5090
A9: Inflows, commit case
A10: Gross cash collected before tax by Dec 12 (Plan Check B7) | B10: ='Plan Check'!B7 -> 4024.2085
A11: Net for the quarter, commit case | B11: =B10-B8 -> -1065.7915
A12: Inflows, stretch case
A13: Gross cash, stretch (85 founding annual plus 15 monthly x 2) | B13: =85*Inputs!B44+15*Inputs!C5*2 -> 7158.85
A14: Net for the quarter, stretch case | B14: =B13-B8 -> 2068.85
A15: Monthly run-rate after Dec 12, commit case (contribution minus fixed) | B15: ='Plan Check'!B8*0.7-Inputs!B52 -> -128.88484
A16: Monthly run-rate after Dec 12, stretch case | B16: =(85*Inputs!B44/12+15*Inputs!C5)*0.7-Inputs!B52 -> 122.51208
A18: Reading: the commit case needs about 1,100 CAD of founder funding this quarter and about 130 a month after it; the stretch case is cash positive. One-time estimates are blue and editable.
